Workbook

Sheet RSI_&_MA
A1: Date | B1: Bajaj | C1: Jio_Fin | D1: Chola_Fin | E1: Bajaj_5 | F1: Bajaj_20 | G1: Bajaj_50 | H1: Bajaj_200 | I1: RSI | J1: Gain | K1: Loss | L1: Jio-5 | M1: Jio-20 | N1: Jio_50 | O1: Jio_200 | P1: RSI | Q1: Gain | R1: Loss | S1: Chola_5 | T1: Chola_20 | U1: Chola_50 | V1: Chola_200 | W1: RSI | X1: Gain | Y1: Loss
A2: 45953 | B2: 2176 | C2: 308.9 | D2: 1683
A3: 45951 | B3: 2165 | C3: 311.2 | D3: 1672 | I3: =B3-B2 -> -11 | J3: =IF(I3>0,I3," ") | K3: =IF(I3<0,I3," ") -> -11 | P3: =C3-C2 -> 2.3 | Q3: =IF(P3>0, P3," ") -> 2.3 | R3: =IF(P3<0,P3," ") | W3: =D3-D2 -> -11 | X3: =IF(W3>0,W3," ") | Y3: =IF(W3<0,W3," ") -> -11
A4: 45950 | B4: 2141.8 | C4: 311 | D4: 1675 | I4: =B4-B3 -> -23.2 | J4: =IF(I4>0,I4," ") | K4: =IF(I4<0,I4," ") -> -23.2 | P4: =C4-C3 -> -0.2 | Q4: =IF(P4>0, P4," ") | R4: =IF(P4<0,P4," ") -> -0.2 | W4: =D4-D3 -> 3 | X4: =IF(W4>0,W4," ") -> 3 | Y4: =IF(W4<0,W4," ")
A5: 45947 | B5: 2081.1 | C5: 309.3 | D5: 1655 | I5: =B5-B4 -> -60.7 | J5: =IF(I5>0,I5," ") | K5: =IF(I5<0,I5," ") -> -60.7 | P5: =C5-C4 -> -1.7 | Q5: =IF(P5>0, P5," ") | R5: =IF(P5<0,P5," ") -> -1.7 | W5: =D5-D4 -> -20 | X5: =IF(W5>0,W5," ") | Y5: =IF(W5<0,W5," ") -> -20
A6: 45946 | B6: 2087.9 | C6: 312.1 | D6: 1664.7 | E6: =AVERAGE(B2:B6) -> 2130.36 | I6: =B6-B5 -> 6.8 | J6: =IF(I6>0,I6," ") -> 6.8 | K6: =IF(I6<0,I6," ") | L6: =AVERAGE(C2:C6) -> 310.5 | P6: =C6-C5 -> 2.8 | Q6: =IF(P6>0, P6," ") -> 2.8 | R6: =IF(P6<0,P6," ") | S6: =AVERAGE(D2:D6) -> 1669.94 | W6: =D6-D5 -> 9.7 | X6: =IF(W6>0,W6," ") -> 9.7 | Y6: =IF(W6<0,W6," ")
A7: 45945 | B7: 2082.9 | C7: 312.8 | D7: 1705 | E7: =AVERAGE(B3:B7) -> 2111.74 | I7: =B7-B6 -> -5 | J7: =IF(I7>0,I7," ") | K7: =IF(I7<0,I7," ") -> -5 | L7: =AVERAGE(C3:C7) -> 311.28 | P7: =C7-C6 -> 0.7 | Q7: =IF(P7>0, P7," ") -> 0.7 | R7: =IF(P7<0,P7," ") | S7: =AVERAGE(D3:D7) -> 1674.34 | W7: =D7-D6 -> 40.3 | X7: =IF(W7>0,W7," ") -> 40.3 | Y7: =IF(W7<0,W7," ")
A8: 45944 | B8: 2019.9 | C8: 305.5 | D8: 1650.1 | E8: =AVERAGE(B4:B8) -> 2082.72 | I8: =B8-B7 -> -63 | J8: =IF(I8>0,I8," ") | K8: =IF(I8<0,I8," ") -> -63 | L8: =AVERAGE(C4:C8) -> 310.14 | P8: =C8-C7 -> -7.3 | Q8: =IF(P8>0, P8," ") | R8: =IF(P8<0,P8," ") -> -7.3 | S8: =AVERAGE(D4:D8) -> 1669.96 | W8: =D8-D7 -> -54.9 | X8: =IF(W8>0,W8," ") | Y8: =IF(W8<0,W8," ") -> -54.9
A9: 45943 | B9: 2023.9 | C9: 308.65 | D9: 1643.7 | E9: =AVERAGE(B5:B9) -> 2059.14 | I9: =B9-B8 -> 4 | J9: =IF(I9>0,I9," ") -> 4 | K9: =IF(I9<0,I9," ") | L9: =AVERAGE(C5:C9) -> 309.67 | P9: =C9-C8 -> 3.15 | Q9: =IF(P9>0, P9," ") -> 3.15 | R9: =IF(P9<0,P9," ") | S9: =AVERAGE(D5:D9) -> 1663.7 | W9: =D9-D8 -> -6.4 | X9: =IF(W9>0,W9," ") | Y9: =IF(W9<0,W9," ") -> -6.4
A10: 45940 | B10: 2008.5 | C10: 308.2 | D10: 1615.6 | E10: =AVERAGE(B6:B10) -> 2044.62 | I10: =B10-B9 -> -15.4 | J10: =IF(I10>0,I10," ") | K10: =IF(I10<0,I10," ") -> -15.4 | L10: =AVERAGE(C6:C10) -> 309.45 | P10: =C10-C9 -> -0.45 | Q10: =IF(P10>0, P10," ") | R10: =IF(P10<0,P10," ") -> -0.45 | S10: =AVERAGE(D6:D10) -> 1655.82 | W10: =D10-D9 -> -28.1 | X10: =IF(W10>0,W10," ") | Y10: =IF(W10<0,W10," ") -> -28.1
A11: 45939 | B11: 2012 | C11: 307.15 | D11: 1620.2 | E11: =AVERAGE(B7:B11) -> 2029.44 | I11: =B11-B10 -> 3.5 | J11: =IF(I11>0,I11," ") -> 3.5 | K11: =IF(I11<0,I11," ") | L11: =AVERAGE(C7:C11) -> 308.46 | P11: =C11-C10 -> -1.05 | Q11: =IF(P11>0, P11," ") | R11: =IF(P11<0,P11," ") -> -1.05 | S11: =AVERAGE(D7:D11) -> 1646.92 | W11: =D11-D10 -> 4.6 | X11: =IF(W11>0,W11," ") -> 4.6 | Y11: =IF(W11<0,W11," ")
A12: 45938 | B12: 2010.2 | C12: 304.7 | D12: 1610.3 | E12: =AVERAGE(B8:B12) -> 2014.9 | I12: =B12-B11 -> -1.8 | J12: =IF(I12>0,I12," ") | K12: =IF(I12<0,I12," ") -> -1.8 | L12: =AVERAGE(C8:C12) -> 306.84 | P12: =C12-C11 -> -2.45 | Q12: =IF(P12>0, P12," ") | R12: =IF(P12<0,P12," ") -> -2.45 | S12: =AVERAGE(D8:D12) -> 1627.98 | W12: =D12-D11 -> -9.9 | X12: =IF(W12>0,W12," ") | Y12: =IF(W12<0,W12," ") -> -9.9
A13: 45937 | B13: 2030 | C13: 310.6 | D13: 1626.7 | E13: =AVERAGE(B9:B13) -> 2016.92 | I13: =B13-B12 -> 19.8 | J13: =IF(I13>0,I13," ") -> 19.8 | K13: =IF(I13<0,I13," ") | L13: =AVERAGE(C9:C13) -> 307.86 | P13: =C13-C12 -> 5.9 | Q13: =IF(P13>0, P13," ") -> 5.9 | R13: =IF(P13<0,P13," ") | S13: =AVERAGE(D9:D13) -> 1623.3 | W13: =D13-D12 -> 16.4 | X13: =IF(W13>0,W13," ") -> 16.4 | Y13: =IF(W13<0,W13," ")
A14: 45936 | B14: 2031.1 | C14: 306.1 | D14: 1646.8 | E14: =AVERAGE(B10:B14) -> 2018.36 | I14: =B14-B13 -> 1.1 | J14: =IF(I14>0,I14," ") -> 1.1 | K14: =IF(I14<0,I14," ") | L14: =AVERAGE(C10:C14) -> 307.35 | P14: =C14-C13 -> -4.5 | Q14: =IF(P14>0, P14," ") | R14: =IF(P14<0,P14," ") -> -4.5 | S14: =AVERAGE(D10:D14) -> 1623.92 | W14: =D14-D13 -> 20.1 | X14: =IF(W14>0,W14," ") -> 20.1 | Y14: =IF(W14<0,W14," ")
A15: 45933 | B15: 1994.2 | C15: 302.6 | D15: 1572 | E15: =AVERAGE(B11:B15) -> 2015.5 | I15: =B15-B14 -> -36.9 | J15: =IF(I15>0,I15," ") | K15: =IF(I15<0,I15," ") -> -36.9 | L15: =AVERAGE(C11:C15) -> 306.23 | P15: =C15-C14 -> -3.5 | Q15: =IF(P15>0, P15," ") | R15: =IF(P15<0,P15," ") -> -3.5 | S15: =AVERAGE(D11:D15) -> 1615.2 | W15: =D15-D14 -> -74.8 | X15: =IF(W15>0,W15," ") | Y15: =IF(W15<0,W15," ") -> -74.8
A16: 45931 | B16: 2010 | C16: 300.8 | D16: 1603 | E16: =AVERAGE(B12:B16) -> 2015.1 | I16: =B16-B15 -> 15.8 | J16: =IF(I16>0,I16," ") -> 15.8 | K16: =IF(I16<0,I16," ") | L16: =AVERAGE(C12:C16) -> 304.96 | P16: =C16-C15 -> -1.8 | Q16: =IF(P16>0, P16," ") | R16: =IF(P16<0,P16," ") -> -1.8 | S16: =AVERAGE(D12:D16) -> 1611.76 | W16: =D16-D15 -> 31 | X16: =IF(W16>0,W16," ") -> 31 | Y16: =IF(W16<0,W16," ")
A17: 45930 | B17: 2001 | C17: 294 | D17: 1610.8 | E17: =AVERAGE(B13:B17) -> 2013.26 | I17: =B17-B16 -> -9 | J17: =IF(I17>0,I17," ") | K17: =IF(I17<0,I17," ") -> -9 | L17: =AVERAGE(C13:C17) -> 302.82 | P17: =C17-C16 -> -6.8 | Q17: =IF(P17>0, P17," ") | R17: =IF(P17<0,P17," ") -> -6.8 | S17: =AVERAGE(D13:D17) -> 1611.86 | W17: =D17-D16 -> 7.8 | X17: =IF(W17>0,W17," ") -> 7.8 | Y17: =IF(W17<0,W17," ")
... A20: 45925 | B20: 2033 | C20: 301.6 | D20: 1591 | E20: =AVERAGE(B16:B20) -> 2011.8 | I20: =B20-B19 -> 30 | J20: =IF(I20>0,I20," ") -> 30 | K20: =IF(I20<0,I20," ") | L20: =AVERAGE(C16:C20) -> 297.59 | P20: =C20-C19 -> 5.25 | Q20: =IF(P20>0, P20," ") -> 5.25 | R20: =IF(P20<0,P20," ") | S20: =AVERAGE(D16:D20) -> 1594.36 | W20: =D20-D19 -> 18.7 | X20: =IF(W20>0,W20," ") -> 18.7 | Y20: =IF(W20<0,W20," ")
A21: 45924 | B21: 2070.1 | C21: 306.25 | D21: 1627.5 | E21: =AVERAGE(B17:B21) -> 2023.82 | F21: =AVERAGE(B2:B21) -> 2049.68 | I21: =B21-B20 -> 37.1 | J21: =IF(I21>0,I21," ") -> 37.1 | K21: =IF(I21<0,I21," ") | L21: =AVERAGE(C17:C21) -> 298.68 | M21: =AVERAGE(C2:C21) -> 305.65 | P21: =C21-C20 -> 4.65 | Q21: =IF(P21>0, P21," ") -> 4.65 | R21: =IF(P21<0,P21," ") | S21: =AVERAGE(D17:D21) -> 1599.26 | T21: =AVERAGE(D2:D21) -> 1631.97 | W21: =D21-D20 -> 36.5 | X21: =IF(W21>0,W21," ") -> 36.5 | Y21: =IF(W21<0,W21," ")
A22: 45923 | B22: 2084 | C22: 313.05 | D22: 1623.7 | E22: =AVERAGE(B18:B22) -> 2040.42 | F22: =AVERAGE(B3:B22) -> 2045.08 | I22: =B22-B21 -> 13.9 | J22: =IF(I22>0,I22," ") -> 13.9 | K22: =IF(I22<0,I22," ") | L22: =AVERAGE(C18:C22) -> 302.49 | M22: =AVERAGE(C3:C22) -> 305.8575 | P22: =C22-C21 -> 6.8 | Q22: =IF(P22>0, P22," ") -> 6.8 | R22: =IF(P22<0,P22," ") | S22: =AVERAGE(D18:D22) -> 1601.84 | T22: =AVERAGE(D3:D22) -> 1629.005 | W22: =D22-D21 -> -3.8 | X22: =IF(W22>0,W22," ") | Y22: =IF(W22<0,W22," ") -> -3.8
A23: 45922 | B23: 2068.6 | C23: 313.7 | D23: 1628 | E23: =AVERAGE(B19:B23) -> 2051.74 | F23: =AVERAGE(B4:B23) -> 2040.26 | I23: =B23-B22 -> -15.4 | J23: =IF(I23>0,I23," ") | K23: =IF(I23<0,I23," ") -> -15.4 | L23: =AVERAGE(C19:C23) -> 306.19 | M23: =AVERAGE(C4:C23) -> 305.9825 | P23: =C23-C22 -> 0.65 | Q23: =IF(P23>0, P23," ") -> 0.65 | R23: =IF(P23<0,P23," ") | S23: =AVERAGE(D19:D23) -> 1608.5 | T23: =AVERAGE(D4:D23) -> 1626.805 | W23: =D23-D22 -> 4.3 | X23: =IF(W23>0,W23," ") -> 4.3 | Y23: =IF(W23<0,W23," ")
A24: 45919 | B24: 2070.5 | C24: 317.6 | D24: 1595.4 | E24: =AVERAGE(B20:B24) -> 2065.24 | F24: =AVERAGE(B5:B24) -> 2036.695 | I24: =B24-B23 -> 1.9 | J24: =IF(I24>0,I24," ") -> 1.9 | K24: =IF(I24<0,I24," ") | L24: =AVERAGE(C20:C24) -> 310.44 | M24: =AVERAGE(C5:C24) -> 306.3125 | P24: =C24-C23 -> 3.9 | Q24: =IF(P24>0, P24," ") -> 3.9 | R24: =IF(P24<0,P24," ") | S24: =AVERAGE(D20:D24) -> 1613.12 | T24: =AVERAGE(D5:D24) -> 1622.825 | W24: =D24-D23 -> -32.6 | X24: =IF(W24>0,W24," ") | Y24: =IF(W24<0,W24," ") -> -32.6
A25: 45918 | B25: 2064.5 | C25: 317.3 | D25: 1581 | E25: =AVERAGE(B21:B25) -> 2071.54 | F25: =AVERAGE(B6:B25) -> 2035.865 | I25: =B25-B24 -> -6 | J25: =IF(I25>0,I25," ") | K25: =IF(I25<0,I25," ") -> -6 | L25: =AVERAGE(C21:C25) -> 313.58 | M25: =AVERAGE(C6:C25) -> 306.7125 | P25: =C25-C24 -> -0.3 | Q25: =IF(P25>0, P25," ") | R25: =IF(P25<0,P25," ") -> -0.3 | S25: =AVERAGE(D21:D25) -> 1611.12 | T25: =AVERAGE(D6:D25) -> 1619.125 | W25: =D25-D24 -> -14.4 | X25: =IF(W25>0,W25," ") | Y25: =IF(W25<0,W25," ") -> -14.4
A26: 45917 | B26: 2060 | C26: 315.85 | D26: 1577 | E26: =AVERAGE(B22:B26) -> 2069.52 | F26: =AVERAGE(B7:B26) -> 2034.47 | I26: =B26-B25 -> -4.5 | J26: =IF(I26>0,I26," ") | K26: =IF(I26<0,I26," ") -> -4.5 | L26: =AVERAGE(C22:C26) -> 315.5 | M26: =AVERAGE(C7:C26) -> 306.9 | P26: =C26-C25 -> -1.45 | Q26: =IF(P26>0, P26," ") | R26: =IF(P26<0,P26," ") -> -1.45 | S26: =AVERAGE(D22:D26) -> 1601.02 | T26: =AVERAGE(D7:D26) -> 1614.74 | W26: =D26-D25 -> -4 | X26: =IF(W26>0,W26," ") | Y26: =IF(W26<0,W26," ") -> -4
A27: 45916 | B27: 2082 | C27: 315.8 | D27: 1586 | E27: =AVERAGE(B23:B27) -> 2069.12 | F27: =AVERAGE(B8:B27) -> 2034.425 | I27: =B27-B26 -> 22 | J27: =IF(I27>0,I27," ") -> 22 | K27: =IF(I27<0,I27," ") | L27: =AVERAGE(C23:C27) -> 316.05 | M27: =AVERAGE(C8:C27) -> 307.05 | P27: =C27-C26 -> -0.05 | Q27: =IF(P27>0, P27," ") | R27: =IF(P27<0,P27," ") -> -0.05 | S27: =AVERAGE(D23:D27) -> 1593.48 | T27: =AVERAGE(D8:D27) -> 1608.79 | W27: =D27-D26 -> 9 | X27: =IF(W27>0,W27," ") -> 9 | Y27: =IF(W27<0,W27," ")
A28: 45915 | B28: 2080.8 | C28: 315.5 | D28: 1519.5 | E28: =AVERAGE(B24:B28) -> 2071.56 | F28: =AVERAGE(B9:B28) -> 2037.47 | I28: =B28-B27 -> -1.2 | J28: =IF(I28>0,I28," ") | K28: =IF(I28<0,I28," ") -> -1.2 | L28: =AVERAGE(C24:C28) -> 316.41 | M28: =AVERAGE(C9:C28) -> 307.55 | P28: =C28-C27 -> -0.3 | Q28: =IF(P28>0, P28," ") | R28: =IF(P28<0,P28," ") -> -0.3 | S28: =AVERAGE(D24:D28) -> 1571.78 | T28: =AVERAGE(D9:D28) -> 1602.26 | W28: =D28-D27 -> -66.5 | X28: =IF(W28>0,W28," ") | Y28: =IF(W28<0,W28," ") -> -66.5
A29: 45912 | B29: 2083.2 | C29: 311.2 | D29: 1511 | E29: =AVERAGE(B25:B29) -> 2074.1 | F29: =AVERAGE(B10:B29) -> 2040.435 | I29: =B29-B28 -> 2.4 | J29: =IF(I29>0,I29," ") -> 2.4 | K29: =IF(I29<0,I29," ") | L29: =AVERAGE(C25:C29) -> 315.13 | M29: =AVERAGE(C10:C29) -> 307.6775 | P29: =C29-C28 -> -4.3 | Q29: =IF(P29>0, P29," ") | R29: =IF(P29<0,P29," ") -> -4.3 | S29: =AVERAGE(D25:D29) -> 1554.9 | T29: =AVERAGE(D10:D29) -> 1595.625 | W29: =D29-D28 -> -8.5 | X29: =IF(W29>0,W29," ") | Y29: =IF(W29<0,W29," ") -> -8.5
A30: 45911 | B30: 2037 | C30: 310.9 | D30: 1494 | E30: =AVERAGE(B26:B30) -> 2068.6 | F30: =AVERAGE(B11:B30) -> 2041.86 | I30: =B30-B29 -> -46.2 | J30: =IF(I30>0,I30," ") | K30: =IF(I30<0,I30," ") -> -46.2 | L30: =AVERAGE(C26:C30) -> 313.85 | M30: =AVERAGE(C11:C30) -> 307.8125 | P30: =C30-C29 -> -0.3 | Q30: =IF(P30>0, P30," ") | R30: =IF(P30<0,P30," ") -> -0.3 | S30: =AVERAGE(D26:D30) -> 1537.5 | T30: =AVERAGE(D11:D30) -> 1589.545 | W30: =D30-D29 -> -17 | X30: =IF(W30>0,W30," ") | Y30: =IF(W30<0,W30," ") -> -17
A31: 45910 | B31: 2038 | C31: 310.35 | D31: 1528.4 | E31: =AVERAGE(B27:B31) -> 2064.2 | F31: =AVERAGE(B12:B31) -> 2043.16 | I31: =B31-B30 -> 1 | J31: =IF(I31>0,I31," ") -> 1 | K31: =IF(I31<0,I31," ") | L31: =AVERAGE(C27:C31) -> 312.75 | M31: =AVERAGE(C12:C31) -> 307.9725 | P31: =C31-C30 -> -0.55 | Q31: =IF(P31>0, P31," ") | R31: =IF(P31<0,P31," ") -> -0.55 | S31: =AVERAGE(D27:D31) -> 1527.78 | T31: =AVERAGE(D12:D31) -> 1584.955 | W31: =D31-D30 -> 34.4 | X31: =IF(W31>0,W31," ") -> 34.4 | Y31: =IF(W31<0,W31," ")
A32: 45909 | B32: 2026.6 | C32: 308.6 | D32: 1506 | E32: =AVERAGE(B28:B32) -> 2053.12 | F32: =AVERAGE(B13:B32) -> 2043.98 | I32: =B32-B31 -> -11.4 | J32: =IF(I32>0,I32," ") | K32: =IF(I32<0,I32," ") -> -11.4 | L32: =AVERAGE(C28:C32) -> 311.31 | M32: =AVERAGE(C13:C32) -> 308.1675 | P32: =C32-C31 -> -1.75 | Q32: =IF(P32>0, P32," ") | R32: =IF(P32<0,P32," ") -> -1.75 | S32: =AVERAGE(D28:D32) -> 1511.78 | T32: =AVERAGE(D13:D32) -> 1579.74 | W32: =D32-D31 -> -22.4 | X32: =IF(W32>0,W32," ") | Y32: =IF(W32<0,W32," ") -> -22.4
... A50: 45881 | B50: 1905 | C50: 326.9 | D50: 1449 | E50: =AVERAGE(B46:B50) -> 1942.3 | F50: =AVERAGE(B31:B50) -> 1964.91 | I50: =B50-B49 -> -12 | J50: =IF(I50>0,I50," ") | K50: =IF(I50<0,I50," ") -> -12 | L50: =AVERAGE(C46:C50) -> 329.23 | M50: =AVERAGE(C31:C50) -> 318.3325 | P50: =C50-C49 -> -3.9 | Q50: =IF(P50>0, P50," ") | R50: =IF(P50<0,P50," ") -> -3.9 | S50: =AVERAGE(D46:D50) -> 1482.46 | T50: =AVERAGE(D31:D50) -> 1481.895 | W50: =D50-D49 -> -10.1 | X50: =IF(W50>0,W50," ") | Y50: =IF(W50<0,W50," ") -> -10.1
A51: 45880 | B51: 1929.3 | C51: 327.9 | D51: 1481 | E51: =AVERAGE(B47:B51) -> 1933.38 | F51: =AVERAGE(B32:B51) -> 1959.475 | G51: =AVERAGE(B2:B51) -> 2017.034 | I51: =B51-B50 -> 24.3 | J51: =IF(I51>0,I51," ") -> 24.3 | K51: =IF(I51<0,I51," ") | L51: =AVERAGE(C47:C51) -> 328.53 | M51: =AVERAGE(C32:C51) -> 319.21 | N51: =AVERAGE(C2:C51) -> 312.769 | P51: =C51-C50 -> 1 | Q51: =IF(P51>0, P51," ") -> 1 | R51: =IF(P51<0,P51," ") | S51: =AVERAGE(D47:D51) -> 1473.62 | T51: =AVERAGE(D32:D51) -> 1479.525 | U51: =AVERAGE(D2:D51) -> 1557.478 | W51: =D51-D50 -> 32 | X51: =IF(W51>0,W51," ") -> 32 | Y51: =IF(W51<0,W51," ")
A52: 45877 | B52: 1919 | C52: 321 | D52: 1451 | E52: =AVERAGE(B48:B52) -> 1918.18 | F52: =AVERAGE(B33:B52) -> 1954.095 | G52: =AVERAGE(B3:B52) -> 2011.894 | I52: =B52-B51 -> -10.3 | J52: =IF(I52>0,I52," ") | K52: =IF(I52<0,I52," ") -> -10.3 | L52: =AVERAGE(C48:C52) -> 326.79 | M52: =AVERAGE(C33:C52) -> 319.83 | N52: =AVERAGE(C3:C52) -> 313.011 | P52: =C52-C51 -> -6.9 | Q52: =IF(P52>0, P52," ") | R52: =IF(P52<0,P52," ") -> -6.9 | S52: =AVERAGE(D48:D52) -> 1459.82 | T52: =AVERAGE(D33:D52) -> 1476.775 | U52: =AVERAGE(D3:D52) -> 1552.838 | W52: =D52-D51 -> -30 | X52: =IF(W52>0,W52," ") | Y52: =IF(W52<0,W52," ") -> -30
A53: 45876 | B53: 1920.9 | C53: 327.4 | D53: 1488 | E53: =AVERAGE(B49:B53) -> 1918.24 | F53: =AVERAGE(B34:B53) -> 1949.64 | G53: =AVERAGE(B4:B53) -> 2007.012 | I53: =B53-B52 -> 1.9 | J53: =IF(I53>0,I53," ") -> 1.9 | K53: =IF(I53<0,I53," ") | L53: =AVERAGE(C49:C53) -> 326.8 | M53: =AVERAGE(C34:C53) -> 320.6575 | N53: =AVERAGE(C4:C53) -> 313.335 | P53: =C53-C52 -> 6.4 | Q53: =IF(P53>0, P53," ") -> 6.4 | R53: =IF(P53<0,P53," ") | S53: =AVERAGE(D49:D53) -> 1465.62 | T53: =AVERAGE(D34:D53) -> 1476.62 | U53: =AVERAGE(D4:D53) -> 1549.158 | W53: =D53-D52 -> 37 | X53: =IF(W53>0,W53," ") -> 37 | Y53: =IF(W53<0,W53," ")
A54: 45875 | B54: 1926 | C54: 326 | D54: 1454.9 | E54: =AVERAGE(B50:B54) -> 1920.04 | F54: =AVERAGE(B35:B54) -> 1945.19 | G54: =AVERAGE(B5:B54) -> 2002.696 | I54: =B54-B53 -> 5.1 | J54: =IF(I54>0,I54," ") -> 5.1 | K54: =IF(I54<0,I54," ") | L54: =AVERAGE(C50:C54) -> 325.84 | M54: =AVERAGE(C35:C54) -> 321.4575 | N54: =AVERAGE(C5:C54) -> 313.635 | P54: =C54-C53 -> -1.4 | Q54: =IF(P54>0, P54," ") | R54: =IF(P54<0,P54," ") -> -1.4 | S54: =AVERAGE(D50:D54) -> 1464.78 | T54: =AVERAGE(D35:D54) -> 1474.815 | U54: =AVERAGE(D5:D54) -> 1544.756 | W54: =D54-D53 -> -33.1 | X54: =IF(W54>0,W54," ") | Y54: =IF(W54<0,W54," ") -> -33.1
A55: 45874 | B55: 1942 | C55: 332.6 | D55: 1470.8 | E55: =AVERAGE(B51:B55) -> 1927.44 | F55: =AVERAGE(B36:B55) -> 1942.14 | G55: =AVERAGE(B6:B55) -> 1999.914 | I55: =B55-B54 -> 16 | J55: =IF(I55>0,I55," ") -> 16 | K55: =IF(I55<0,I55," ") | L55: =AVERAGE(C51:C55) -> 326.98 | M55: =AVERAGE(C36:C55) -> 322.5975 | N55: =AVERAGE(C6:C55) -> 314.101 | P55: =C55-C54 -> 6.6 | Q55: =IF(P55>0, P55," ") -> 6.6 | R55: =IF(P55<0,P55," ") | S55: =AVERAGE(D51:D55) -> 1469.14 | T55: =AVERAGE(D36:D55) -> 1475.205 | U55: =AVERAGE(D6:D55) -> 1541.072 | W55: =D55-D54 -> 15.9 | X55: =IF(W55>0,W55," ") -> 15.9 | Y55: =IF(W55<0,W55," ")
A56: 45873 | B56: 1932 | C56: 334.85 | D56: 1471 | E56: =AVERAGE(B52:B56) -> 1927.98 | F56: =AVERAGE(B37:B56) -> 1940.19 | G56: =AVERAGE(B7:B56) -> 1996.796 | I56: =B56-B55 -> -10 | J56: =IF(I56>0,I56," ") | K56: =IF(I56<0,I56," ") -> -10 | L56: =AVERAGE(C52:C56) -> 328.37 | M56: =AVERAGE(C37:C56) -> 323.645 | N56: =AVERAGE(C7:C56) -> 314.556 | P56: =C56-C55 -> 2.25 | Q56: =IF(P56>0, P56," ") -> 2.25 | R56: =IF(P56<0,P56," ") | S56: =AVERAGE(D52:D56) -> 1467.14 | T56: =AVERAGE(D37:D56) -> 1476.555 | U56: =AVERAGE(D7:D56) -> 1537.198 | W56: =D56-D55 -> 0.2 | X56: =IF(W56>0,W56," ") -> 0.2 | Y56: =IF(W56<0,W56," ")
A57: 45870 | B57: 1920 | C57: 329.85 | D57: 1420.5 | E57: =AVERAGE(B53:B57) -> 1928.18 | F57: =AVERAGE(B38:B57) -> 1938.34 | G57: =AVERAGE(B8:B57) -> 1993.538 | I57: =B57-B56 -> -12 | J57: =IF(I57>0,I57," ") | K57: =IF(I57<0,I57," ") -> -12 | L57: =AVERAGE(C53:C57) -> 330.14 | M57: =AVERAGE(C38:C57) -> 324.5525 | N57: =AVERAGE(C8:C57) -> 314.897 | P57: =C57-C56 -> -5 | Q57: =IF(P57>0, P57," ") | R57: =IF(P57<0,P57," ") -> -5 | S57: =AVERAGE(D53:D57) -> 1461.04 | T57: =AVERAGE(D38:D57) -> 1475.93 | U57: =AVERAGE(D8:D57) -> 1531.508 | W57: =D57-D56 -> -50.5 | X57: =IF(W57>0,W57," ") | Y57: =IF(W57<0,W57," ") -> -50.5
A58: 45869 | B58: 1952 | C58: 329 | D58: 1435.6 | E58: =AVERAGE(B54:B58) -> 1934.4 | F58: =AVERAGE(B39:B58) -> 1938.795 | G58: =AVERAGE(B9:B58) -> 1992.18 | I58: =B58-B57 -> 32 | J58: =IF(I58>0,I58," ") -> 32 | K58: =IF(I58<0,I58," ") | L58: =AVERAGE(C54:C58) -> 330.46 | M58: =AVERAGE(C39:C58) -> 325.2825 | N58: =AVERAGE(C9:C58) -> 315.367 | P58: =C58-C57 -> -0.85 | Q58: =IF(P58>0, P58," ") | R58: =IF(P58<0,P58," ") -> -0.85 | S58: =AVERAGE(D54:D58) -> 1450.56 | T58: =AVERAGE(D39:D58) -> 1475.195 | U58: =AVERAGE(D9:D58) -> 1527.218 | W58: =D58-D57 -> 15.1 | X58: =IF(W58>0,W58," ") -> 15.1 | Y58: =IF(W58<0,W58," ")
A59: 45868 | B59: 1960 | C59: 320 | D59: 1480 | E59: =AVERAGE(B55:B59) -> 1941.2 | F59: =AVERAGE(B40:B59) -> 1940.995 | G59: =AVERAGE(B10:B59) -> 1990.902 | I59: =B59-B58 -> 8 | J59: =IF(I59>0,I59," ") -> 8 | K59: =IF(I59<0,I59," ") | L59: =AVERAGE(C55:C59) -> 329.26 | M59: =AVERAGE(C40:C59) -> 325.7175 | N59: =AVERAGE(C10:C59) -> 315.594 | P59: =C59-C58 -> -9 | Q59: =IF(P59>0, P59," ") | R59: =IF(P59<0,P59," ") -> -9 | S59: =AVERAGE(D55:D59) -> 1455.58 | T59: =AVERAGE(D40:D59) -> 1478.01 | U59: =AVERAGE(D10:D59) -> 1523.944 | W59: =D59-D58 -> 44.4 | X59: =IF(W59>0,W59," ") -> 44.4 | Y59: =IF(W59<0,W59," ")
...

Sheet Trade Log
A1: Date | B1: Time | C1: Company | D1: Action | E1: Qty | F1: Entry Price (₹) | G1: Exit Price (₹) | H1: Amount Invested (₹) | I1: Amount Received (₹) | J1: P&L (₹)
A2: 45944 | B2: 0.45 | C2: Bajaj Finserv | D2: BUY | E2: 100 | F2: 2029.7 | G2: - | H2: =E2*F2 -> 202970 | I2: -
A3: 45944 | B3: 0.44583333 | C3: JioFin | D3: BUY | E3: 1000 | F3: 308 | G3: - | H3: =E3*F3 -> 308000 | I3: -
A4: 45944 | B4: 0.14097222 | C4: Bajaj Finserv | D4: SELL | E4: 100 | G4: 2020 | I4: =E4*G4 -> 202000 | J4: =I4-H2 -> -970
A5: 45944 | B5: 0.44722222 | C5: CholaFin | D5: BUY | E5: 180 | F5: 1657.5 | G5: - | H5: =E5*F5 -> 298350 | I5: -
A6: 45945 | B6: 0.13888889 | C6: JioFin | D6: SELL | E6: 1000 | G6: 312.55 | I6: =E6*G6 -> 312550 | J6: =I6-H3 -> 4550
A7: 45946 | B7: 0.50694444 | C7: CholaFin | D7: SELL | E7: 180 | G7: 1671 | I7: =E7*G7 -> 300780 | J7: =I7-H5 -> 2430
A8: 45946 | B8: 0.50763889 | C8: Bajaj Finserv | D8: BUY | E8: 50 | F8: 2095.78 | H8: =E8*F8 -> 104789
A9: 45946 | B9: 0.52083333 | C9: JioFin | D9: BUY | E9: 1000 | F9: 311.8 | H9: =E9*F9 -> 311800
A10: 45947 | B10: 0.10347222 | C10: CholaFin | D10: BUY | E10: 300 | F10: 1661.8 | H10: =E10*F10 -> 498540 | I10: =E10*F10 -> 498540
A11: 45947 | B11: 0.13194444 | C11: CholaFin | D11: SELL | E11: 300 | F11: - | G11: 1663.8 | H11: _ | I11: =E11*G11 -> 499140 | J11: =I11-H10 -> 600
A12: 45947 | B12: 0.45694444 | C12: JioFin | D12: SELL | E12: 1000 | F12: - | G12: 309.3 | H12: _ | I12: =E12*G12 -> 309300 | J12: =I12-H9 -> -2500
A13: 45947 | B13: 0.14166667 | C13: CholaFin | D13: BUY | E13: 200 | F13: 1654.3 | H13: =E13*F13 -> 330860
A14: 45950 | B14: 0.13958333 | C14: CholaFin | D14: SELL | E14: 200 | G14: 1673.4 | I14: =E14*G14 -> 334680 | J14: =I14-H13 -> 3820
A15: 45951 | B15: 0.11597222 | C15: CholaFin | D15: BUY | E15: 100 | F15: 1670.3 | H15: =E15*F15 -> 167030
A16: 45953 | B16: 0.4125 | C16: JioFin | D16: BUY | E16: 500 | F16: 302 | H16: =E16*F16 -> 151000
A17: 45953 | B17: 0.097222222 | C17: JioFin | D17: SELL | E17: 500 | F17: 307.45 | I17: =E17*F17 -> 153725 | J17: =I17-H16 -> 2725
A18: 45954 | B18: 0.47777778 | C18: CholaFin | D18: SELL | E18: 100 | G18: 1710 | I18: =E18*G18 -> 171000 | J18: =I18-H15 -> 3970
A19: 45954 | B19: 0.097222222 | C19: Bajaj Finserv | D19: SELL | E19: 50 | G19: 2112 | I19: =E19*G19 -> 105600 | J19: =I19-H8 -> 811
A20: 45959 | B20: 0.42916667 | C20: Bajaj Finserv | D20: BUY | E20: 20 | F20: 2151 | H20: =E20*F20 -> 43020
A21: 45959 | B21: 0.53472222 | C21: Bajaj Finserv | D21: SELL | E21: 20 | G21: 2088 | I21: =E21*G21 -> 41760 | J21: =I21-H20 -> -1260
I22: Totol Profit | J22: =J4+J6+J7+J11+J12+J14+J17+J18+J19+J21 -> 14176 | L22: Overall Gain | M22: =(1014176/1000000) -> 1.014176

Sheet PortFolio Return
B1: Invested Amount(2 Week) | C1: Received Amount | D1: Expected Gain | E1: Expected Loss | F1: Expected Amount | G1: Received Amount
A2: Bajaj | B2: ='Trade Log'!H2+'Trade Log'!H8+'Trade Log'!H20 -> 350779 | C2: ='Trade Log'!I4+'Trade Log'!I19+'Trade Log'!I19 -> 413200 | D2: =B2*18.41% -> 64578.414 | E2: =B3*-23.11% -> -178131.88 | F2: =B2*-2.78% -> -9751.6562 | G2: =C2-B2 -> 62421
A3: Jio | B3: ='Trade Log'!H3+'Trade Log'!H9+'Trade Log'!H16 -> 770800 | C3: ='Trade Log'!I6+'Trade Log'!I12+'Trade Log'!I17 -> 775575 | D3: =B3*4.68% -> 36073.44 | E3: =B3*-2.98% -> -22969.84 | F3: =B3*0.19% -> 1464.52 | G3: =C3-B3 -> 4775
A4: Chola | B4: ='Trade Log'!H5+'Trade Log'!H10+'Trade Log'!H13+'Trade Log'!H15 -> 1294780 | C4: ='Trade Log'!I7+'Trade Log'!I11+'Trade Log'!I14+'Trade Log'!I18 -> 1305600 | D4: =B4*20.61% -> 266854.16 | E4: =B4*-27.65% -> -358006.67 | F4: =B4*-3.64% -> -47129.992 | G4: =C4-B4 -> 10820
B5: =SUM(B2:B4) -> 2416359 | C5: =SUM(C2:C4) -> 2494375 | F5: =SUM(F2:F4) -> -55417.128 | G5: =G2+G3+G4 -> 78016
B6: Bajaj | C6: Jio | D6: Chola | F6: =(B5-F5)/B5 -> 1.0229341 | G6: =(B5-G5)/B5 -> 0.96771341
A7: Avg Gain | B7: =AVERAGE('RSI_&_MA'!J3:J250) -> 18.414615 | C7: =AVERAGE('RSI_&_MA'!Q3:Q250) -> 4.3567227 | D7: =AVERAGE('RSI_&_MA'!X3:X250) -> 20.204745
A8: Avg Loss | B8: =AVERAGE('RSI_&_MA'!K3:K250) -> -23.965678 | C8: =AVERAGE('RSI_&_MA'!R3:R250) -> -3.975969 | D8: =AVERAGE('RSI_&_MA'!Y3:Y250) -> -27.475225
A9: Expected | B9: =AVERAGE(B7:B8) -> -2.7755313 | C9: =AVERAGE(C7:C8) -> 0.19037685 | D9: =AVERAGE(D7:D8) -> -3.6352403 | E9: =AVERAGE(B9:D9) -> -2.0734649
A10: Actual | B10: =(C2-B2)/C2*100 -> 15.106728 | C10: =(C3-B3)/B3*100 -> 0.61948625 | D10: =(C4-B4)/C4*100 -> 0.82873775 | E10: =AVERAGE(B10:D10) -> 5.5183173
D11: Overall | E11: =E10+E9 -> 3.4448524
L22: verall
